OrderBookSim/OrderBookSim/Outputs/Log1361618946.txt
0--INFO	Added rule
0--INFO	Added rule
0--INFO	Added rule
0--INFO	Added rule
70--INFO	Enqueued order: Price: 0.00, Volume: 61, Type: SELL, Market Order: 1, Participant: 1, Stock:[ID: 0, Symbol: GOOG], Time: 70, OrderNumber: 0
90--INFO	Enqueued order: Price: 2147483647.00, Volume: 605, Type: BUY, Market Order: 1, Participant: 0, Stock:[ID: 0, Symbol: GOOG], Time: 90, OrderNumber: 1
91--INFO	Last Price Set:100.00
91--INFO	Notified Traders of trade91---Trade ID: 0, Price: 100.00, Volume: 61 between ID:[0] and ID:[1]
140--INFO	Enqueued order: Price: 0.00, Volume: 546, Type: SELL, Market Order: 1, Participant: 1, Stock:[ID: 0, Symbol: GOOG], Time: 140, OrderNumber: 2
141--INFO	Last Price Set:100.00
141--INFO	Notified Traders of trade141---Trade ID: 1, Price: 100.00, Volume: 544 between ID:[0] and ID:[1]
180--INFO	Enqueued order: Price: 2147483647.00, Volume: 15, Type: BUY, Market Order: 1, Participant: 0, Stock:[ID: 0, Symbol: GOOG], Time: 180, OrderNumber: 3
181--INFO	Last Price Set:100.00
181--INFO	Notified Traders of trade181---Trade ID: 2, Price: 100.00, Volume: 2 between ID:[0] and ID:[1]
210--INFO	Enqueued order: Price: 0.00, Volume: 17, Type: SELL, Market Order: 1, Participant: 1, Stock:[ID: 0, Symbol: GOOG], Time: 210, OrderNumber: 4
211--INFO	Last Price Set:100.00
211--INFO	Notified Traders of trade211---Trade ID: 3, Price: 100.00, Volume: 13 between ID:[0] and ID:[1]
237--INFO	Enqueued order: Price: 0.00, Volume: 557, Type: SELL, Market Order: 1, Participant: 2, Stock:[ID: 0, Symbol: GOOG], Time: 237, OrderNumber: 5
270--INFO	Enqueued order: Price: 2147483647.00, Volume: 472, Type: BUY, Market Order: 1, Participant: 0, Stock:[ID: 0, Symbol: GOOG], Time: 270, OrderNumber: 6
271--INFO	Last Price Set:100.00
271--INFO	Notified Traders of trade271---Trade ID: 4, Price: 100.00, Volume: 4 between ID:[0] and ID:[1]
271--INFO	Last Price Set:100.00
271--INFO	Notified Traders of trade271---Trade ID: 5, Price: 100.00, Volume: 468 between ID:[0] and ID:[2]
280--INFO	Enqueued order: Price: 2147483647.00, Volume: 294, Type: BUY, Market Order: 1, Participant: 1, Stock:[ID: 0, Symbol: GOOG], Time: 280, OrderNumber: 7
281--INFO	Last Price Set:100.00
281--INFO	Notified Traders of trade281---Trade ID: 6, Price: 100.00, Volume: 294 between ID:[1] and ID:[2]
350--INFO	Enqueued order: Price: 0.00, Volume: 325, Type: SELL, Market Order: 1, Participant: 1, Stock:[ID: 0, Symbol: GOOG], Time: 350, OrderNumber: 8
360--INFO	Enqueued order: Price: 2147483647.00, Volume: 646, Type: BUY, Market Order: 1, Participant: 0, Stock:[ID: 0, Symbol: GOOG], Time: 360, OrderNumber: 9
361--INFO	Last Price Set:100.00
361--INFO	Notified Traders of trade361---Trade ID: 7, Price: 100.00, Volume: 557 between ID:[0] and ID:[2]
361--INFO	Last Price Set:100.00
361--INFO	Notified Traders of trade361---Trade ID: 8, Price: 100.00, Volume: 89 between ID:[0] and ID:[1]
420--INFO	Enqueued order: Price: 2147483647.00, Volume: 9, Type: BUY, Market Order: 1, Participant: 1, Stock:[ID: 0, Symbol: GOOG], Time: 420, OrderNumber: 10
450--INFO	Enqueued order: Price: 2147483647.00, Volume: 400, Type: BUY, Market Order: 1, Participant: 0, Stock:[ID: 0, Symbol: GOOG], Time: 450, OrderNumber: 11
451--INFO	Last Price Set:100.00
451--INFO	Notified Traders of trade451---Trade ID: 9, Price: 100.00, Volume: 325 between ID:[0] and ID:[1]
474--INFO	Enqueued order: Price: 0.00, Volume: 1492, Type: SELL, Market Order: 1, Participant: 2, Stock:[ID: 0, Symbol: GOOG], Time: 474, OrderNumber: 12
475--INFO	Last Price Set:100.00
475--INFO	Notified Traders of trade475---Trade ID: 10, Price: 100.00, Volume: 9 between ID:[1] and ID:[2]
475--INFO	Last Price Set:100.00
475--INFO	Notified Traders of trade475---Trade ID: 11, Price: 100.00, Volume: 75 between ID:[0] and ID:[2]
490--INFO	Enqueued order: Price: 0.00, Volume: 894, Type: SELL, Market Order: 1, Participant: 1, Stock:[ID: 0, Symbol: GOOG], Time: 490, OrderNumber: 13
540--INFO	Enqueued order: Price: 100.04, Volume: 954, Type: SELL, Market Order: 0, Participant: 0, Stock:[ID: 0, Symbol: GOOG], Time: 540, OrderNumber: 14
560--INFO	Enqueued order: Price: 100.08, Volume: 423, Type: SELL, Market Order: 0, Participant: 1, Stock:[ID: 0, Symbol: GOOG], Time: 560, OrderNumber: 15
599--INFO	Enqueued order: Price: 2147483647.00, Volume: 3777, Type: BUY, Market Order: 1, Participant: 3, Stock:[ID: 0, Symbol: GOOG], Time: 599, OrderNumber: 16
600--INFO	Last Price Set:100.00
600--INFO	Notified Traders of trade600---Trade ID: 12, Price: 100.00, Volume: 1408 between ID:[3] and ID:[2]
600--INFO	Last Price Set:100.00
600--INFO	Notified Traders of trade600---Trade ID: 13, Price: 100.00, Volume: 894 between ID:[3] and ID:[1]
600--INFO	Last Price Set:100.04
600--INFO	Notified Traders of trade600---Trade ID: 14, Price: 100.04, Volume: 954 between ID:[3] and ID:[0]
600--INFO	Last Price Set:100.08
600--INFO	Notified Traders of trade600---Trade ID: 15, Price: 100.08, Volume: 423 between ID:[3] and ID:[1]
630--INFO	Enqueued order: Price: 100.00, Volume: 452, Type: BUY, Market Order: 0, Participant: 0, Stock:[ID: 0, Symbol: GOOG], Time: 630, OrderNumber: 17
630--INFO	Enqueued order: Price: 0.00, Volume: 940, Type: SELL, Market Order: 1, Participant: 1, Stock:[ID: 0, Symbol: GOOG], Time: 630, OrderNumber: 18
632--INFO	Last Price Set:100.08
632--INFO	Notified Traders of trade632---Trade ID: 16, Price: 100.08, Volume: 98 between ID:[3] and ID:[1]
632--INFO	Last Price Set:100.00
632--INFO	Notified Traders of trade632---Trade ID: 17, Price: 100.00, Volume: 452 between ID:[0] and ID:[1]
700--INFO	Enqueued order: Price: 2147483647.00, Volume: 150, Type: BUY, Market Order: 1, Participant: 1, Stock:[ID: 0, Symbol: GOOG], Time: 700, OrderNumber: 19
711--INFO	Enqueued order: Price: 2147483647.00, Volume: 4167, Type: BUY, Market Order: 1, Participant: 2, Stock:[ID: 0, Symbol: GOOG], Time: 711, OrderNumber: 20
712--INFO	Last Price Set:100.00
712--INFO	Notified Traders of trade712---Trade ID: 18, Price: 100.00, Volume: 390 between ID:[2] and ID:[1]
720--INFO	Enqueued order: Price: 2147483647.00, Volume: 784, Type: BUY, Market Order: 1, Participant: 0, Stock:[ID: 0, Symbol: GOOG], Time: 720, OrderNumber: 21
770--INFO	Enqueued order: Price: 0.00, Volume: 620, Type: SELL, Market Order: 1, Participant: 1, Stock:[ID: 0, Symbol: GOOG], Time: 770, OrderNumber: 22
771--INFO	Last Price Set:100.00
771--INFO	Notified Traders of trade771---Trade ID: 19, Price: 100.00, Volume: 620 between ID:[2] and ID:[1]
810--INFO	Enqueued order: Price: 100.06, Volume: 631, Type: SELL, Market Order: 0, Participant: 0, Stock:[ID: 0, Symbol: GOOG], Time: 810, OrderNumber: 23
811--INFO	Last Price Set:100.06
811--INFO	Notified Traders of trade811---Trade ID: 20, Price: 100.06, Volume: 150 between ID:[1] and ID:[0]
811--INFO	Last Price Set:100.06
811--INFO	Notified Traders of trade811---Trade ID: 21, Price: 100.06, Volume: 481 between ID:[2] and ID:[0]
840--INFO	Enqueued order: Price: 0.00, Volume: 829, Type: SELL, Market Order: 1, Participant: 1, Stock:[ID: 0, Symbol: GOOG], Time: 840, OrderNumber: 24
841--INFO	Last Price Set:100.06
841--INFO	Notified Traders of trade841---Trade ID: 22, Price: 100.06, Volume: 829 between ID:[2] and ID:[1]
900--INFO	Enqueued order: Price: 100.06, Volume: 728, Type: BUY, Market Order: 0, Participant: 0, Stock:[ID: 0, Symbol: GOOG], Time: 900, OrderNumber: 25
910--INFO	Enqueued order: Price: 0.00, Volume: 524, Type: SELL, Market Order: 1, Participant: 1, Stock:[ID: 0, Symbol: GOOG], Time: 910, OrderNumber: 26
911--INFO	Last Price Set:100.06
911--INFO	Notified Traders of trade911---Trade ID: 23, Price: 100.06, Volume: 524 between ID:[2] and ID:[1]
980--INFO	Enqueued order: Price: 2147483647.00, Volume: 579, Type: BUY, Market Order: 1, Participant: 1, Stock:[ID: 0, Symbol: GOOG], Time: 980, OrderNumber: 27
990--INFO	Enqueued order: Price: 0.00, Volume: 374, Type: SELL, Market Order: 1, Participant: 0, Stock:[ID: 0, Symbol: GOOG], Time: 990, OrderNumber: 28
991--INFO	Last Price Set:100.06
991--INFO	Notified Traders of trade991---Trade ID: 24, Price: 100.06, Volume: 374 between ID:[2] and ID:[0]
