OrderBookSim/OrderBookSim/Outputs/Output1361618946.txt
0,100,0,0,0
1,100,0,0,0
2,100,0,0,0
3,100,0,0,0
4,100,0,0,0
5,100,0,0,0
6,100,0,0,0
7,100,0,0,0
8,100,0,0,0
9,100,0,0,0
10,100,0,0,0
11,100,0,0,0
12,100,0,0,0
13,100,0,0,0
14,100,0,0,0
15,100,0,0,0
16,100,0,0,0
17,100,0,0,0
18,100,0,0,0
19,100,0,0,0
20,100,0,0,0
21,100,0,0,0
22,100,0,0,0
23,100,0,0,0
24,100,0,0,0
25,100,0,0,0
26,100,0,0,0
27,100,0,0,0
28,100,0,0,0
29,100,0,0,0
30,100,0,0,0
31,100,0,0,0
32,100,0,0,0
33,100,0,0,0
34,100,0,0,0
35,100,0,0,0
36,100,0,0,0
37,100,0,0,0
38,100,0,0,0
39,100,0,0,0
40,100,0,0,0
41,100,0,0,0
42,100,0,0,0
43,100,0,0,0
44,100,0,0,0
45,100,0,0,0
46,100,0,0,0
47,100,0,0,0
48,100,0,0,0
49,100,0,0,0
50,100,0,0,0
51,100,0,0,0
52,100,0,0,0
53,100,0,0,0
54,100,0,0,0
55,100,0,0,0
56,100,0,0,0
57,100,0,0,0
58,100,0,0,0
59,100,0,0,0
60,100,0,0,0
61,100,0,0,0
62,100,0,0,0
63,100,0,0,0
64,100,0,0,0
65,100,0,0,0
66,100,0,0,0
67,100,0,0,0
68,100,0,0,0
69,100,0,0,0
70,100,0,0,0
71,100,0,1,0
72,100,0,1,0
73,100,0,1,0
74,100,0,1,0
75,100,0,1,0
76,100,0,1,0
77,100,0,1,0
78,100,0,1,0
79,100,0,1,0
80,100,0,1,0
81,100,0,1,0
82,100,0,1,0
83,100,0,1,0
84,100,0,1,0
85,100,0,1,0
86,100,0,1,0
87,100,0,1,0
88,100,0,1,0
89,100,0,1,0
90,100,0,1,0
91,100,1,0,1
92,100,1,0,1
93,100,1,0,1
94,100,1,0,1
95,100,1,0,1
96,100,1,0,1
97,100,1,0,1
98,100,1,0,1
99,100,1,0,1
100,100,1,0,1
101,100,1,0,1
102,100,1,0,1
103,100,1,0,1
104,100,1,0,1
105,100,1,0,1
106,100,1,0,1
107,100,1,0,1
108,100,1,0,1
109,100,1,0,1
110,100,1,0,1
111,100,1,0,1
112,100,1,0,1
113,100,1,0,1
114,100,1,0,1
115,100,1,0,1
116,100,1,0,1
117,100,1,0,1
118,100,1,0,1
119,100,1,0,1
120,100,1,0,1
121,100,1,0,1
122,100,1,0,1
123,100,1,0,1
124,100,1,0,1
125,100,1,0,1
126,100,1,0,1
127,100,1,0,1
128,100,1,0,1
129,100,1,0,1
130,100,1,0,1
131,100,1,0,1
132,100,1,0,1
133,100,1,0,1
134,100,1,0,1
135,100,1,0,1
136,100,1,0,1
137,100,1,0,1
138,100,1,0,1
139,100,1,0,1
140,100,1,0,1
141,100,0,1,2
142,100,0,1,2
143,100,0,1,2
144,100,0,1,2
145,100,0,1,2
146,100,0,1,2
147,100,0,1,2
148,100,0,1,2
149,100,0,1,2
150,100,0,1,2
151,100,0,1,2
152,100,0,1,2
153,100,0,1,2
154,100,0,1,2
155,100,0,1,2
156,100,0,1,2
157,100,0,1,2
158,100,0,1,2
159,100,0,1,2
160,100,0,1,2
161,100,0,1,2
162,100,0,1,2
163,100,0,1,2
164,100,0,1,2
165,100,0,1,2
166,100,0,1,2
167,100,0,1,2
168,100,0,1,2
169,100,0,1,2
170,100,0,1,2
171,100,0,1,2
172,100,0,1,2
173,100,0,1,2
174,100,0,1,2
175,100,0,1,2
176,100,0,1,2
177,100,0,1,2
178,100,0,1,2
179,100,0,1,2
180,100,0,1,2
181,100,1,0,3
182,100,1,0,3
183,100,1,0,3
184,100,1,0,3
185,100,1,0,3
186,100,1,0,3
187,100,1,0,3
188,100,1,0,3
189,100,1,0,3
190,100,1,0,3
191,100,1,0,3
192,100,1,0,3
193,100,1,0,3
194,100,1,0,3
195,100,1,0,3
196,100,1,0,3
197,100,1,0,3
198,100,1,0,3
199,100,1,0,3
200,100,1,0,3
201,100,1,0,3
202,100,1,0,3
203,100,1,0,3
204,100,1,0,3
205,100,1,0,3
206,100,1,0,3
207,100,1,0,3
208,100,1,0,3
209,100,1,0,3
210,100,1,0,3
211,100,0,1,4
212,100,0,1,4
213,100,0,1,4
214,100,0,1,4
215,100,0,1,4
216,100,0,1,4
217,100,0,1,4
218,100,0,1,4
219,100,0,1,4
220,100,0,1,4
221,100,0,1,4
222,100,0,1,4
223,100,0,1,4
224,100,0,1,4
225,100,0,1,4
226,100,0,1,4
227,100,0,1,4
228,100,0,1,4
229,100,0,1,4
230,100,0,1,4
231,100,0,1,4
232,100,0,1,4
233,100,0,1,4
234,100,0,1,4
235,100,0,1,4
236,100,0,1,4
237,100,0,1,4
238,100,0,2,4
239,100,0,2,4
240,100,0,2,4
241,100,0,2,4
242,100,0,2,4
243,100,0,2,4
244,100,0,2,4
245,100,0,2,4
246,100,0,2,4
247,100,0,2,4
248,100,0,2,4
249,100,0,2,4
250,100,0,2,4
251,100,0,2,4
252,100,0,2,4
253,100,0,2,4
254,100,0,2,4
255,100,0,2,4
256,100,0,2,4
257,100,0,2,4
258,100,0,2,4
259,100,0,2,4
260,100,0,2,4
261,100,0,2,4
262,100,0,2,4
263,100,0,2,4
264,100,0,2,4
265,100,0,2,4
266,100,0,2,4
267,100,0,2,4
268,100,0,2,4
269,100,0,2,4
270,100,0,2,4
271,100,0,1,6
272,100,0,1,6
273,100,0,1,6
274,100,0,1,6
275,100,0,1,6
276,100,0,1,6
277,100,0,1,6
278,100,0,1,6
279,100,0,1,6
280,100,0,1,6
281,100,0,1,7
282,100,0,1,7
283,100,0,1,7
284,100,0,1,7
285,100,0,1,7
286,100,0,1,7
287,100,0,1,7
288,100,0,1,7
289,100,0,1,7
290,100,0,1,7
291,100,0,1,7
292,100,0,1,7
293,100,0,1,7
294,100,0,1,7
295,100,0,1,7
296,100,0,1,7
297,100,0,1,7
298,100,0,1,7
299,100,0,1,7
300,100,0,1,7
301,100,0,1,7
302,100,0,1,7
303,100,0,1,7
304,100,0,1,7
305,100,0,1,7
306,100,0,1,7
307,100,0,1,7
308,100,0,1,7
309,100,0,1,7
310,100,0,1,7
311,100,0,1,7
312,100,0,1,7
313,100,0,1,7
314,100,0,1,7
315,100,0,1,7
316,100,0,1,7
317,100,0,1,7
318,100,0,1,7
319,100,0,1,7
320,100,0,1,7
321,100,0,1,7
322,100,0,1,7
323,100,0,1,7
324,100,0,1,7
325,100,0,1,7
326,100,0,1,7
327,100,0,1,7
328,100,0,1,7
329,100,0,1,7
330,100,0,1,7
331,100,0,1,7
332,100,0,1,7
333,100,0,1,7
334,100,0,1,7
335,100,0,1,7
336,100,0,1,7
337,100,0,1,7
338,100,0,1,7
339,100,0,1,7
340,100,0,1,7
341,100,0,1,7
342,100,0,1,7
343,100,0,1,7
344,100,0,1,7
345,100,0,1,7
346,100,0,1,7
347,100,0,1,7
348,100,0,1,7
349,100,0,1,7
350,100,0,1,7
351,100,0,2,7
352,100,0,2,7
353,100,0,2,7
354,100,0,2,7
355,100,0,2,7
356,100,0,2,7
357,100,0,2,7
358,100,0,2,7
359,100,0,2,7
360,100,0,2,7
361,100,0,1,9
362,100,0,1,9
363,100,0,1,9
364,100,0,1,9
365,100,0,1,9
366,100,0,1,9
367,100,0,1,9
368,100,0,1,9
369,100,0,1,9
370,100,0,1,9
371,100,0,1,9
372,100,0,1,9
373,100,0,1,9
374,100,0,1,9
375,100,0,1,9
376,100,0,1,9
377,100,0,1,9
378,100,0,1,9
379,100,0,1,9
380,100,0,1,9
381,100,0,1,9
382,100,0,1,9
383,100,0,1,9
384,100,0,1,9
385,100,0,1,9
386,100,0,1,9
387,100,0,1,9
388,100,0,1,9
389,100,0,1,9
390,100,0,1,9
391,100,0,1,9
392,100,0,1,9
393,100,0,1,9
394,100,0,1,9
395,100,0,1,9
396,100,0,1,9
397,100,0,1,9
398,100,0,1,9
399,100,0,1,9
400,100,0,1,9
401,100,0,1,9
402,100,0,1,9
403,100,0,1,9
404,100,0,1,9
405,100,0,1,9
406,100,0,1,9
407,100,0,1,9
408,100,0,1,9
409,100,0,1,9
410,100,0,1,9
411,100,0,1,9
412,100,0,1,9
413,100,0,1,9
414,100,0,1,9
415,100,0,1,9
416,100,0,1,9
417,100,0,1,9
418,100,0,1,9
419,100,0,1,9
420,100,0,1,9
421,100,1,1,9
422,100,1,1,9
423,100,1,1,9
424,100,1,1,9
425,100,1,1,9
426,100,1,1,9
427,100,1,1,9
428,100,1,1,9
429,100,1,1,9
430,100,1,1,9
431,100,1,1,9
432,100,1,1,9
433,100,1,1,9
434,100,1,1,9
435,100,1,1,9
436,100,1,1,9
437,100,1,1,9
438,100,1,1,9
439,100,1,1,9
440,100,1,1,9
441,100,1,1,9
442,100,1,1,9
443,100,1,1,9
444,100,1,1,9
445,100,1,1,9
446,100,1,1,9
447,100,1,1,9
448,100,1,1,9
449,100,1,1,9
450,100,1,1,9
451,100,2,0,10
452,100,2,0,10
453,100,2,0,10
454,100,2,0,10
455,100,2,0,10
456,100,2,0,10
457,100,2,0,10
458,100,2,0,10
459,100,2,0,10
460,100,2,0,10
461,100,2,0,10
462,100,2,0,10
463,100,2,0,10
464,100,2,0,10
465,100,2,0,10
466,100,2,0,10
467,100,2,0,10
468,100,2,0,10
469,100,2,0,10
470,100,2,0,10
471,100,2,0,10
472,100,2,0,10
473,100,2,0,10
474,100,2,0,10
475,100,0,1,12
476,100,0,1,12
477,100,0,1,12
478,100,0,1,12
479,100,0,1,12
480,100,0,1,12
481,100,0,1,12
482,100,0,1,12
483,100,0,1,12
484,100,0,1,12
485,100,0,1,12
486,100,0,1,12
487,100,0,1,12
488,100,0,1,12
489,100,0,1,12
490,100,0,1,12
491,100,0,2,12
492,100,0,2,12
493,100,0,2,12
494,100,0,2,12
495,100,0,2,12
496,100,0,2,12
497,100,0,2,12
498,100,0,2,12
499,100,0,2,12
500,100,0,2,12
501,100,0,2,12
502,100,0,2,12
503,100,0,2,12
504,100,0,2,12
505,100,0,2,12
506,100,0,2,12
507,100,0,2,12
508,100,0,2,12
509,100,0,2,12
510,100,0,2,12
511,100,0,2,12
512,100,0,2,12
513,100,0,2,12
514,100,0,2,12
515,100,0,2,12
516,100,0,2,12
517,100,0,2,12
518,100,0,2,12
519,100,0,2,12
520,100,0,2,12
521,100,0,2,12
522,100,0,2,12
523,100,0,2,12
524,100,0,2,12
525,100,0,2,12
526,100,0,2,12
527,100,0,2,12
528,100,0,2,12
529,100,0,2,12
530,100,0,2,12
531,100,0,2,12
532,100,0,2,12
533,100,0,2,12
534,100,0,2,12
535,100,0,2,12
536,100,0,2,12
537,100,0,2,12
538,100,0,2,12
539,100,0,2,12
540,100,0,2,12
541,100,0,3,12
542,100,0,3,12
543,100,0,3,12
544,100,0,3,12
545,100,0,3,12
546,100,0,3,12
547,100,0,3,12
548,100,0,3,12
549,100,0,3,12
550,100,0,3,12
551,100,0,3,12
552,100,0,3,12
553,100,0,3,12
554,100,0,3,12
555,100,0,3,12
556,100,0,3,12
557,100,0,3,12
558,100,0,3,12
559,100,0,3,12
560,100,0,3,12
561,100,0,4,12
562,100,0,4,12
563,100,0,4,12
564,100,0,4,12
565,100,0,4,12
566,100,0,4,12
567,100,0,4,12
568,100,0,4,12
569,100,0,4,12
570,100,0,4,12
